Workbook

Sheet Plan annuel
A1: Jour | B1: Date | C1: Semaine | D1: Ancien Testament | E1: Nouveau Testament | F1: Type lecture NT | G1: Passage miroir conseillé | H1: Thème commun | I1: Nature du lien | J1: Lien théologique | K1: Suivi | L1: Notes personnelles | M1: Audio AT (S21) | N1: Audio NT (S21) | O1: Audio miroir (S21)
A2: 1 | B2: 01/01 | C2: 1 | D2: Genèse 1–2 | E2: Jean 1.1-5 | F2: Écho thématique | G2: — | H2: Création et nouvelle création | I2: Création / accomplissement eschatologique | J2: Le texte de l'AT contemple l'œuvre créatrice de Dieu ; le NT la relit à la lumière du Christ et de la nouvelle création. | K2: À lire | M2: =HYPERLINK("https://www.bible.com/fr/audio-bible/152/GEN.1.S21","▶ Écouter AT") -> ▶ Écouter AT | N2: =HYPERLINK("https://www.bible.com/fr/audio-bible/152/JHN.1.S21","▶ Écouter NT") -> ▶ Écouter NT
A3: 2 | B3: 02/01 | C3: 1 | D3: Genèse 3–5 | E3: Romains 5 | F3: Lecture NT intégrale | G3: Éphésiens 2.4-10 | H3: Grâce et pardon | I3: Écho thématique | J3: La miséricorde de Dieu dans l'AT s'épanouit dans la grâce manifestée en Jésus-Christ. | K3: À lire | M3: =HYPERLINK("https://www.bible.com/fr/audio-bible/152/GEN.3.S21","▶ Écouter AT") -> ▶ Écouter AT | N3: =HYPERLINK("https://www.bible.com/fr/audio-bible/152/ROM.5.S21","▶ Écouter NT") -> ▶ Écouter NT | O3: =HYPERLINK("https://www.bible.com/fr/audio-bible/152/EPH.2.S21","▶ Écouter miroir") -> ▶ Écouter miroir
A4: 3 | B4: 03/01 | C4: 1 | D4: Genèse 6–7 | E4: Hébreux 8.6-13 | F4: Écho thématique | G4: — | H4: Alliance et promesses | I4: Écho thématique | J4: L'alliance de l'AT prépare et éclaire l'accomplissement des promesses en Christ. | K4: À lire | M4: =HYPERLINK("https://www.bible.com/fr/audio-bible/152/GEN.6.S21","▶ Écouter AT") -> ▶ Écouter AT | N4: =HYPERLINK("https://www.bible.com/fr/audio-bible/152/HEB.8.S21","▶ Écouter NT") -> ▶ Écouter NT
A5: 4 | B5: 04/01 | C5: 1 | D5: Genèse 8–10 | E5: Actes 15 | F5: Lecture NT intégrale | G5: — | H5: Nations et universalité du salut | I5: Déploiement du dessein de Dieu | J5: Ce que l'AT annonce concernant les nations trouve son développement dans l'universalité de l'Évangile. | K5: À lire | M5: =HYPERLINK("https://www.bible.com/fr/audio-bible/152/GEN.8.S21","▶ Écouter AT") -> ▶ Écouter AT | N5: =HYPERLINK("https://www.bible.com/fr/audio-bible/152/ACT.15.S21","▶ Écouter NT") -> ▶ Écouter NT
A6: 5 | B6: 05/01 | C6: 1 | D6: Genèse 11–12 | E6: Actes 13 | F6: Lecture NT intégrale | G6: — | H6: Nations et universalité du salut | I6: Déploiement du dessein de Dieu | J6: Ce que l'AT annonce concernant les nations trouve son développement dans l'universalité de l'Évangile. | K6: À lire | M6: =HYPERLINK("https://www.bible.com/fr/audio-bible/152/GEN.11.S21","▶ Écouter AT") -> ▶ Écouter AT | N6: =HYPERLINK("https://www.bible.com/fr/audio-bible/152/ACT.13.S21","▶ Écouter NT") -> ▶ Écouter NT
A7: 6 | B7: 06/01 | C7: 1 | D7: Genèse 13–15 | E7: Matthieu 15 | F7: Lecture NT intégrale | G7: — | H7: Nations et universalité du salut | I7: Déploiement du dessein de Dieu | J7: Ce que l'AT annonce concernant les nations trouve son développement dans l'universalité de l'Évangile. | K7: À lire | M7: =HYPERLINK("https://www.bible.com/fr/audio-bible/152/GEN.13.S21","▶ Écouter AT") -> ▶ Écouter AT | N7: =HYPERLINK("https://www.bible.com/fr/audio-bible/152/MAT.15.S21","▶ Écouter NT") -> ▶ Écouter NT
A8: 7 | B8: 07/01 | C8: 1 | D8: Genèse 16–17 | E8: Matthieu 14 | F8: Lecture NT intégrale | G8: — | H8: Nations et universalité du salut | I8: Déploiement du dessein de Dieu | J8: Ce que l'AT annonce concernant les nations trouve son développement dans l'universalité de l'Évangile. | K8: À lire | M8: =HYPERLINK("https://www.bible.com/fr/audio-bible/152/GEN.16.S21","▶ Écouter AT") -> ▶ Écouter AT | N8: =HYPERLINK("https://www.bible.com/fr/audio-bible/152/MAT.14.S21","▶ Écouter NT") -> ▶ Écouter NT
A9: 8 | B9: 08/01 | C9: 2 | D9: Genèse 18–20 | E9: Éphésiens 2.4-10 | F9: Écho thématique | G9: — | H9: Grâce et pardon | I9: Écho thématique | J9: La miséricorde de Dieu dans l'AT s'épanouit dans la grâce manifestée en Jésus-Christ. | K9: À lire | M9: =HYPERLINK("https://www.bible.com/fr/audio-bible/152/GEN.18.S21","▶ Écouter AT") -> ▶ Écouter AT | N9: =HYPERLINK("https://www.bible.com/fr/audio-bible/152/EPH.2.S21","▶ Écouter NT") -> ▶ Écouter NT
A10: 9 | B10: 09/01 | C10: 2 | D10: Genèse 21–22 | E10: Hébreux 10.10-14 | F10: Écho thématique | G10: — | H10: Sacrifice et expiation | I10: Typologie / accomplissement | J10: Le sacrifice de l'AT fonctionne comme une ombre qui éclaire l'offrande parfaite du Christ. | K10: À lire | M10: =HYPERLINK("https://www.bible.com/fr/audio-bible/152/GEN.21.S21","▶ Écouter AT") -> ▶ Écouter AT | N10: =HYPERLINK("https://www.bible.com/fr/audio-bible/152/HEB.10.S21","▶ Écouter NT") -> ▶ Écouter NT
A11: 10 | B11: 10/01 | C11: 2 | D11: Genèse 23–25 | E11: Hébreux 8.6-13 | F11: Écho thématique | G11: — | H11: Alliance et promesses | I11: Écho thématique | J11: L'alliance de l'AT prépare et éclaire l'accomplissement des promesses en Christ. | K11: À lire | M11: =HYPERLINK("https://www.bible.com/fr/audio-bible/152/GEN.23.S21","▶ Écouter AT") -> ▶ Écouter AT | N11: =HYPERLINK("https://www.bible.com/fr/audio-bible/152/HEB.8.S21","▶ Écouter NT") -> ▶ Écouter NT
A12: 11 | B12: 11/01 | C12: 2 | D12: Genèse 26–27 | E12: Hébreux 8.6-13 | F12: Écho thématique | G12: — | H12: Alliance et promesses | I12: Écho thématique | J12: L'alliance de l'AT prépare et éclaire l'accomplissement des promesses en Christ. | K12: À lire | M12: =HYPERLINK("https://www.bible.com/fr/audio-bible/152/GEN.26.S21","▶ Écouter AT") -> ▶ Écouter AT | N12: =HYPERLINK("https://www.bible.com/fr/audio-bible/152/HEB.8.S21","▶ Écouter NT") -> ▶ Écouter NT
A13: 12 | B13: 12/01 | C13: 2 | D13: Genèse 28–30 | E13: Galates 4 | F13: Lecture NT intégrale | G13: — | H13: Alliance et promesses | I13: Écho thématique | J13: L'alliance de l'AT prépare et éclaire l'accomplissement des promesses en Christ. | K13: À lire | M13: =HYPERLINK("https://www.bible.com/fr/audio-bible/152/GEN.28.S21","▶ Écouter AT") -> ▶ Écouter AT | N13: =HYPERLINK("https://www.bible.com/fr/audio-bible/152/GAL.4.S21","▶ Écouter NT") -> ▶ Écouter NT
A14: 13 | B14: 13/01 | C14: 2 | D14: Genèse 31–33 | E14: Matthieu 20 | F14: Lecture NT intégrale | G14: Hébreux 8.6-13 | H14: Alliance et promesses | I14: Écho thématique | J14: L'alliance de l'AT prépare et éclaire l'accomplissement des promesses en Christ. | K14: À lire | M14: =HYPERLINK("https://www.bible.com/fr/audio-bible/152/GEN.31.S21","▶ Écouter AT") -> ▶ Écouter AT | N14: =HYPERLINK("https://www.bible.com/fr/audio-bible/152/MAT.20.S21","▶ Écouter NT") -> ▶ Écouter NT | O14: =HYPERLINK("https://www.bible.com/fr/audio-bible/152/HEB.8.S21","▶ Écouter miroir") -> ▶ Écouter miroir
A15: 14 | B15: 14/01 | C15: 2 | D15: Genèse 34–35 | E15: Matthieu 19 | F15: Lecture NT intégrale | G15: Hébreux 8.6-13 | H15: Alliance et promesses | I15: Écho thématique | J15: L'alliance de l'AT prépare et éclaire l'accomplissement des promesses en Christ. | K15: À lire | M15: =HYPERLINK("https://www.bible.com/fr/audio-bible/152/GEN.34.S21","▶ Écouter AT") -> ▶ Écouter AT | N15: =HYPERLINK("https://www.bible.com/fr/audio-bible/152/MAT.19.S21","▶ Écouter NT") -> ▶ Écouter NT | O15: =HYPERLINK("https://www.bible.com/fr/audio-bible/152/HEB.8.S21","▶ Écouter miroir") -> ▶ Écouter miroir
A16: 15 | B16: 15/01 | C16: 3 | D16: Genèse 36–38 | E16: Actes 26 | F16: Lecture NT intégrale | G16: Hébreux 8.6-13 | H16: Alliance et promesses | I16: Écho thématique | J16: L'alliance de l'AT prépare et éclaire l'accomplissement des promesses en Christ. | K16: À lire | M16: =HYPERLINK("https://www.bible.com/fr/audio-bible/152/GEN.36.S21","▶ Écouter AT") -> ▶ Écouter AT | N16: =HYPERLINK("https://www.bible.com/fr/audio-bible/152/ACT.26.S21","▶ Écouter NT") -> ▶ Écouter NT | O16: =HYPERLINK("https://www.bible.com/fr/audio-bible/152/HEB.8.S21","▶ Écouter miroir") -> ▶ Écouter miroir
A17: 16 | B17: 16/01 | C17: 3 | D17: Genèse 39–40 | E17: Actes 24 | F17: Lecture NT intégrale | G17: 1 Pierre 2.21-24 | H17: Souffrance et persévérance | I17: Écho thématique | J17: La souffrance du juste dans l'AT s'éclaire par celle du Christ et l'espérance donnée aux croyants. | K17: À lire | M17: =HYPERLINK("https://www.bible.com/fr/audio-bible/152/GEN.39.S21","▶ Écouter AT") -> ▶ Écouter AT | N17: =HYPERLINK("https://www.bible.com/fr/audio-bible/152/ACT.24.S21","▶ Écouter NT") -> ▶ Écouter NT | O17: =HYPERLINK("https://www.bible.com/fr/audio-bible/152/1PE.2.S21","▶ Écouter miroir") -> ▶ Écouter miroir
A18: 17 | B18: 17/01 | C18: 3 | D18: Genèse 41–43 | E18: Actes 23 | F18: Lecture NT intégrale | G18: 1 Pierre 2.21-24 | H18: Souffrance et persévérance | I18: Écho thématique | J18: La souffrance du juste dans l'AT s'éclaire par celle du Christ et l'espérance donnée aux croyants. | K18: À lire | M18: =HYPERLINK("https://www.bible.com/fr/audio-bible/152/GEN.41.S21","▶ Écouter AT") -> ▶ Écouter AT | N18: =HYPERLINK("https://www.bible.com/fr/audio-bible/152/ACT.23.S21","▶ Écouter NT") -> ▶ Écouter NT | O18: =HYPERLINK("https://www.bible.com/fr/audio-bible/152/1PE.2.S21","▶ Écouter miroir") -> ▶ Écouter miroir
A19: 18 | B19: 18/01 | C19: 3 | D19: Genèse 44–45 | E19: Philémon 1 | F19: Lecture NT intégrale | G19: Éphésiens 4.31-32 | H19: Pardon | I19: Continuité théologique et pratique | J19: Le pardon recherché dans l'AT s'enracine dans le pardon reçu en Christ. | K19: À lire | M19: =HYPERLINK("https://www.bible.com/fr/audio-bible/152/GEN.44.S21","▶ Écouter AT") -> ▶ Écouter AT | N19: =HYPERLINK("https://www.bible.com/fr/audio-bible/152/PHM.1.S21","▶ Écouter NT") -> ▶ Écouter NT | O19: =HYPERLINK("https://www.bible.com/fr/audio-bible/152/EPH.4.S21","▶ Écouter miroir") -> ▶ Écouter miroir
A20: 19 | B20: 19/01 | C20: 3 | D20: Genèse 46–48 | E20: Actes 16 | F20: Lecture NT intégrale | G20: — | H20: Nations et universalité du salut | I20: Déploiement du dessein de Dieu | J20: Ce que l'AT annonce concernant les nations trouve son développement dans l'universalité de l'Évangile. | K20: À lire | M20: =HYPERLINK("https://www.bible.com/fr/audio-bible/152/GEN.46.S21","▶ Écouter AT") -> ▶ Écouter AT | N20: =HYPERLINK("https://www.bible.com/fr/audio-bible/152/ACT.16.S21","▶ Écouter NT") -> ▶ Écouter NT
A21: 20 | B21: 20/01 | C21: 3 | D21: Genèse 49–50 | E21: Actes 14 | F21: Lecture NT intégrale | G21: Éphésiens 3.4-6 | H21: Nations et universalité du salut | I21: Déploiement du dessein de Dieu | J21: Ce que l'AT annonce concernant les nations trouve son développement dans l'universalité de l'Évangile. | K21: À lire | M21: =HYPERLINK("https://www.bible.com/fr/audio-bible/152/GEN.49.S21","▶ Écouter AT") -> ▶ Écouter AT | N21: =HYPERLINK("https://www.bible.com/fr/audio-bible/152/ACT.14.S21","▶ Écouter NT") -> ▶ Écouter NT | O21: =HYPERLINK("https://www.bible.com/fr/audio-bible/152/EPH.3.S21","▶ Écouter miroir") -> ▶ Écouter miroir
A22: 21 | B22: 21/01 | C22: 3 | D22: Exode 1–3 | E22: 1 Corinthiens 10.1-4 | F22: Écho thématique | G22: — | H22: Exode, salut et libération | I22: Typologie / accomplissement | J22: La sortie de l'esclavage devient une figure du salut et de la vie nouvelle en Christ. | K22: À lire | M22: =HYPERLINK("https://www.bible.com/fr/audio-bible/152/EXO.1.S21","▶ Écouter AT") -> ▶ Écouter AT | N22: =HYPERLINK("https://www.bible.com/fr/audio-bible/152/1CO.10.S21","▶ Écouter NT") -> ▶ Écouter NT
A23: 22 | B23: 22/01 | C23: 4 | D23: Exode 4–5 | E23: 1 Corinthiens 10 | F23: Lecture NT intégrale | G23: — | H23: Exode, salut et libération | I23: Typologie / accomplissement | J23: La sortie de l'esclavage devient une figure du salut et de la vie nouvelle en Christ. | K23: À lire | M23: =HYPERLINK("https://www.bible.com/fr/audio-bible/152/EXO.4.S21","▶ Écouter AT") -> ▶ Écouter AT | N23: =HYPERLINK("https://www.bible.com/fr/audio-bible/152/1CO.10.S21","▶ Écouter NT") -> ▶ Écouter NT
A24: 23 | B24: 23/01 | C24: 4 | D24: Exode 6–8 | E24: 1 Corinthiens 9 | F24: Lecture NT intégrale | G24: — | H24: Exode, salut et libération | I24: Typologie / accomplissement | J24: La sortie de l'esclavage devient une figure du salut et de la vie nouvelle en Christ. | K24: À lire | M24: =HYPERLINK("https://www.bible.com/fr/audio-bible/152/EXO.6.S21","▶ Écouter AT") -> ▶ Écouter AT | N24: =HYPERLINK("https://www.bible.com/fr/audio-bible/152/1CO.9.S21","▶ Écouter NT") -> ▶ Écouter NT
A25: 24 | B25: 24/01 | C25: 4 | D25: Exode 9–11 | E25: 1 Corinthiens 8 | F25: Lecture NT intégrale | G25: — | H25: Exode, salut et libération | I25: Typologie / accomplissement | J25: La sortie de l'esclavage devient une figure du salut et de la vie nouvelle en Christ. | K25: À lire | M25: =HYPERLINK("https://www.bible.com/fr/audio-bible/152/EXO.9.S21","▶ Écouter AT") -> ▶ Écouter AT | N25: =HYPERLINK("https://www.bible.com/fr/audio-bible/152/1CO.8.S21","▶ Écouter NT") -> ▶ Écouter NT
A26: 25 | B26: 25/01 | C26: 4 | D26: Exode 12–13 | E26: Marc 14 | F26: Lecture NT intégrale | G26: — | H26: Sacrifice et expiation | I26: Typologie / accomplissement | J26: Le sacrifice de l'AT fonctionne comme une ombre qui éclaire l'offrande parfaite du Christ. | K26: À lire | M26: =HYPERLINK("https://www.bible.com/fr/audio-bible/152/EXO.12.S21","▶ Écouter AT") -> ▶ Écouter AT | N26: =HYPERLINK("https://www.bible.com/fr/audio-bible/152/MRK.14.S21","▶ Écouter NT") -> ▶ Écouter NT
A27: 26 | B27: 26/01 | C27: 4 | D27: Exode 14–16 | E27: Jean 6 | F27: Lecture NT intégrale | G27: — | H27: Exode, salut et libération | I27: Typologie / accomplissement | J27: La sortie de l'esclavage devient une figure du salut et de la vie nouvelle en Christ. | K27: À lire | M27: =HYPERLINK("https://www.bible.com/fr/audio-bible/152/EXO.14.S21","▶ Écouter AT") -> ▶ Écouter AT | N27: =HYPERLINK("https://www.bible.com/fr/audio-bible/152/JHN.6.S21","▶ Écouter NT") -> ▶ Écouter NT
A28: 27 | B28: 27/01 | C28: 4 | D28: Exode 17–18 | E28: Hébreux 3.7-19 | F28: Écho thématique | G28: — | H28: Désert, épreuve et persévérance | I28: Avertissement / contraste | J28: L'expérience du désert avertit contre l'incrédulité et appelle à persévérer dans la foi. | K28: À lire | M28: =HYPERLINK("https://www.bible.com/fr/audio-bible/152/EXO.17.S21","▶ Écouter AT") -> ▶ Écouter AT | N28: =HYPERLINK("https://www.bible.com/fr/audio-bible/152/HEB.3.S21","▶ Écouter NT") -> ▶ Écouter NT
A29: 28 | B29: 28/01 | C29: 4 | D29: Exode 19–21 | E29: Hébreux 8.6-13 | F29: Écho thématique | G29: — | H29: Alliance et promesses | I29: Écho thématique | J29: L'alliance de l'AT prépare et éclaire l'accomplissement des promesses en Christ. | K29: À lire | M29: =HYPERLINK("https://www.bible.com/fr/audio-bible/152/EXO.19.S21","▶ Écouter AT") -> ▶ Écouter AT | N29: =HYPERLINK("https://www.bible.com/fr/audio-bible/152/HEB.8.S21","▶ Écouter NT") -> ▶ Écouter NT
A30: 29 | B30: 29/01 | C30: 5 | D30: Exode 22–23 | E30: Hébreux 8.6-13 | F30: Écho thématique | G30: — | H30: Alliance et promesses | I30: Écho thématique | J30: L'alliance de l'AT prépare et éclaire l'accomplissement des promesses en Christ. | K30: À lire | M30: =HYPERLINK("https://www.bible.com/fr/audio-bible/152/EXO.22.S21","▶ Écouter AT") -> ▶ Écouter AT | N30: =HYPERLINK("https://www.bible.com/fr/audio-bible/152/HEB.8.S21","▶ Écouter NT") -> ▶ Écouter NT
A31: 30 | B31: 30/01 | C31: 5 | D31: Exode 24–26 | E31: Hébreux 7.23-28 | F31: Écho thématique | G31: — | H31: Prêtrise et médiation | I31: Typologie / accomplissement | J31: La médiation sacerdotale de l'AT conduit au grand-prêtre parfait qu'est Jésus. | K31: À lire | M31: =HYPERLINK("https://www.bible.com/fr/audio-bible/152/EXO.24.S21","▶ Écouter AT") -> ▶ Écouter AT | N31: =HYPERLINK("https://www.bible.com/fr/audio-bible/152/HEB.7.S21","▶ Écouter NT") -> ▶ Écouter NT
A32: 31 | B32: 31/01 | C32: 5 | D32: Exode 27–28 | E32: Hébreux 7.23-28 | F32: Écho thématique | G32: — | H32: Prêtrise et médiation | I32: Typologie / accomplissement | J32: La médiation sacerdotale de l'AT conduit au grand-prêtre parfait qu'est Jésus. | K32: À lire | M32: =HYPERLINK("https://www.bible.com/fr/audio-bible/152/EXO.27.S21","▶ Écouter AT") -> ▶ Écouter AT | N32: =HYPERLINK("https://www.bible.com/fr/audio-bible/152/HEB.7.S21","▶ Écouter NT") -> ▶ Écouter NT
A33: 32 | B33: 01/02 | C33: 5 | D33: Exode 29–31 | E33: Hébreux 7.23-28 | F33: Écho thématique | G33: — | H33: Prêtrise et médiation | I33: Typologie / accomplissement | J33: La médiation sacerdotale de l'AT conduit au grand-prêtre parfait qu'est Jésus. | K33: À lire | M33: =HYPERLINK("https://www.bible.com/fr/audio-bible/152/EXO.29.S21","▶ Écouter AT") -> ▶ Écouter AT | N33: =HYPERLINK("https://www.bible.com/fr/audio-bible/152/HEB.7.S21","▶ Écouter NT") -> ▶ Écouter NT
A34: 33 | B34: 02/02 | C34: 5 | D34: Exode 32–33 | E34: Romains 10 | F34: Lecture NT intégrale | G34: — | H34: Alliance et promesses | I34: Écho thématique | J34: L'alliance de l'AT prépare et éclaire l'accomplissement des promesses en Christ. | K34: À lire | M34: =HYPERLINK("https://www.bible.com/fr/audio-bible/152/EXO.32.S21","▶ Écouter AT") -> ▶ Écouter AT | N34: =HYPERLINK("https://www.bible.com/fr/audio-bible/152/ROM.10.S21","▶ Écouter NT") -> ▶ Écouter NT
A35: 34 | B35: 03/02 | C35: 5 | D35: Exode 34–36 | E35: Romains 9 | F35: Lecture NT intégrale | G35: — | H35: Alliance et promesses | I35: Écho thématique | J35: L'alliance de l'AT prépare et éclaire l'accomplissement des promesses en Christ. | K35: À lire | M35: =HYPERLINK("https://www.bible.com/fr/audio-bible/152/EXO.34.S21","▶ Écouter AT") -> ▶ Écouter AT | N35: =HYPERLINK("https://www.bible.com/fr/audio-bible/152/ROM.9.S21","▶ Écouter NT") -> ▶ Écouter NT
A36: 35 | B36: 04/02 | C36: 5 | D36: Exode 37–39 | E36: Galates 6 | F36: Lecture NT intégrale | G36: Hébreux 9.1-12 | H36: Tabernacle et demeure de Dieu | I36: Typologie / accomplissement | J36: Le sanctuaire terrestre annonce l'accès véritable à Dieu ouvert par Christ. | K36: À lire | M36: =HYPERLINK("https://www.bible.com/fr/audio-bible/152/EXO.37.S21","▶ Écouter AT") -> ▶ Écouter AT | N36: =HYPERLINK("https://www.bible.com/fr/audio-bible/152/GAL.6.S21","▶ Écouter NT") -> ▶ Écouter NT | O36: =HYPERLINK("https://www.bible.com/fr/audio-bible/152/HEB.9.S21","▶ Écouter miroir") -> ▶ Écouter miroir
A37: 36 | B37: 05/02 | C37: 6 | D37: Exode 40 ; Lévitique 1 | E37: Hébreux 10 | F37: Lecture NT intégrale | G37: — | H37: Sacrifice et expiation | I37: Typologie / accomplissement | J37: Le sacrifice de l'AT fonctionne comme une ombre qui éclaire l'offrande parfaite du Christ. | K37: À lire | M37: =HYPERLINK("https://www.bible.com/fr/audio-bible/152/LEV.1.S21","▶ Écouter AT") -> ▶ Écouter AT | N37: =HYPERLINK("https://www.bible.com/fr/audio-bible/152/HEB.10.S21","▶ Écouter NT") -> ▶ Écouter NT
A38: 37 | B38: 06/02 | C38: 6 | D38: Lévitique 2–4 | E38: Hébreux 10.10-14 | F38: Écho thématique | G38: — | H38: Sacrifice et expiation | I38: Typologie / accomplissement | J38: Le sacrifice de l'AT fonctionne comme une ombre qui éclaire l'offrande parfaite du Christ. | K38: À lire | M38: =HYPERLINK("https://www.bible.com/fr/audio-bible/152/LEV.2.S21","▶ Écouter AT") -> ▶ Écouter AT | N38: =HYPERLINK("https://www.bible.com/fr/audio-bible/152/HEB.10.S21","▶ Écouter NT") -> ▶ Écouter NT
A39: 38 | B39: 07/02 | C39: 6 | D39: Lévitique 5–6 | E39: Hébreux 10.10-14 | F39: Écho thématique | G39: — | H39: Sacrifice et expiation | I39: Typologie / accomplissement | J39: Le sacrifice de l'AT fonctionne comme une ombre qui éclaire l'offrande parfaite du Christ. | K39: À lire | M39: =HYPERLINK("https://www.bible.com/fr/audio-bible/152/LEV.5.S21","▶ Écouter AT") -> ▶ Écouter AT | N39: =HYPERLINK("https://www.bible.com/fr/audio-bible/152/HEB.10.S21","▶ Écouter NT") -> ▶ Écouter NT
A40: 39 | B40: 08/02 | C40: 6 | D40: Lévitique 7–9 | E40: Hébreux 9 | F40: Lecture NT intégrale | G40: — | H40: Sacrifice et expiation | I40: Typologie / accomplissement | J40: Le sacrifice de l'AT fonctionne comme une ombre qui éclaire l'offrande parfaite du Christ. | K40: À lire | M40: =HYPERLINK("https://www.bible.com/fr/audio-bible/152/LEV.7.S21","▶ Écouter AT") -> ▶ Écouter AT | N40: =HYPERLINK("https://www.bible.com/fr/audio-bible/152/HEB.9.S21","▶ Écouter NT") -> ▶ Écouter NT
...

Sheet Mode d'emploi
A1: PLAN DE LECTURE BIBLIQUE EN 1 AN — AT/NT AVEC LIENS THÉOLOGIQUES
A3: Principe | B3: Toute la Bible est couverte en un an. L'AT est lu dans l'ordre canonique ; les 260 chapitres du NT sont répartis selon leur proximité avec les passages de l'AT.
A4: Pourquoi un « passage miroir » ? | B4: Quand le chapitre NT nécessaire à la couverture intégrale n'offre qu'un lien large avec l'AT, un court passage NT supplémentaire est proposé. Il constitue alors le rapprochement théologique principal du jour.
A5: Lecture quotidienne | B5: Lire l'AT, puis la colonne « Nouveau Testament ». Si la colonne « Passage miroir conseillé » contient une référence, la lire également comme courte clé de rapprochement.
A6: 105 jours d'écho | B6: Le NT ne compte que 260 chapitres pour 365 jours. Les 105 jours sans nouveau chapitre intégral utilisent directement un passage NT en écho : il apparaît alors dans la colonne « Nouveau Testament ».
A7: Nature des liens | B7: Le fichier distingue : promesse/accomplissement, typologie/accomplissement, avertissement/contraste, continuité théologique et pratique, déploiement du dessein de Dieu, ou écho thématique.
A8: Prudence d'interprétation | B8: Un rapprochement thématique n'est pas automatiquement une prophétie. Le plan réserve le langage d'accomplissement aux grands motifs bibliques reconnus et présente les autres relations comme continuité, typologie ou écho.
A9: Thèmes majeurs | B9: Création, chute, alliance, sacrifice, Pâque, Exode, Loi, sainteté, prêtrise, présence, Temple, désert, repos, royauté, Messie, Esprit, nations, mission, souffrance, espérance, résurrection, restauration, nouvelle alliance et nouvelle création.
A10: Rythme | B10: La colonne Date va du 1er janvier au 31 décembre mais le plan peut être commencé n'importe quand en suivant le numéro de jour.
A11: Suivi | B11: La liste déroulante permet : À lire / Lu / À reprendre. La dernière colonne reste libre pour vos notes et versets prioritaires.
A13: Méthode de méditation
A14: 1. | B14: Repérer dans l'AT le problème, la promesse, la figure, l'alliance ou l'action de Dieu.
A15: 2. | B15: Lire le NT et demander : accomplissement, continuité, contraste ou élargissement aux nations ?
A16: 3. | B16: Si un passage miroir est indiqué, l'utiliser pour préciser le lien sans forcer le chapitre NT principal.
A17: 4. | B17: Noter un mot-clé et un verset prioritaire dans chacun des deux Testaments.
A18: 5. | B18: Terminer par une prière issue directement des textes lus.
A20: Version audio
A21: Source principale | B21: Les boutons audio utilisent la Bible Segond 21 sur YouVersion, car cette version dispose d'un audio complet AT + NT et de liens directs par chapitre.
A22: Navigation | B22: Le bouton ouvre le premier chapitre du passage du jour. Pour 2 ou 3 chapitres consécutifs, utiliser simplement « chapitre suivant » dans le lecteur.
A23: Passages partiels | B23: Quand le plan indique seulement quelques versets, le lecteur ouvre le chapitre entier ; la référence du plan indique où commencer/arrêter.

Sheet Couverture NT
A1: Livre NT | B1: Chapitre | C1: Jour attribué | D1: AT associé | E1: Lecture NT intégrale | F1: Miroir si nécessaire
A2: Matthieu | B2: 1 | C2: 56 | D2: Nombres 23–25 | E2: Matthieu 1 | F2: —
A3: Matthieu | B3: 2 | C3: 106 | D3: 2 Samuel 1–2 | E3: Matthieu 2 | F3: —
A4: Matthieu | B4: 3 | C4: 62 | D4: Deutéronome 3–4 | E4: Matthieu 3 | F4: —
A5: Matthieu | B5: 4 | C5: 224 | D5: Psaumes 90–92 | E5: Matthieu 4 | F5: —
A6: Matthieu | B6: 5 | C6: 65 | D6: Deutéronome 10–12 | E6: Matthieu 5 | F6: —
A7: Matthieu | B7: 6 | C7: 63 | D7: Deutéronome 5–7 | E7: Matthieu 6 | F7: —
A8: Matthieu | B8: 7 | C8: 64 | D8: Deutéronome 8–9 | E8: Matthieu 7 | F8: —
A9: Matthieu | B9: 8 | C9: 124 | D9: 2 Rois 1–2 | E9: Matthieu 8 | F9: —
A10: Matthieu | B10: 9 | C10: 125 | D10: 2 Rois 3–5 | E10: Matthieu 9 | F10: —
A11: Matthieu | B11: 10 | C11: 103 | D11: 1 Samuel 24–26 | E11: Matthieu 10 | F11: Luc 1.32-33
A12: Matthieu | B12: 11 | C12: 141 | D12: 1 Chroniques 19–20 | E12: Matthieu 11 | F12: Luc 24.25-27
A13: Matthieu | B13: 12 | C13: 102 | D13: 1 Samuel 22–23 | E13: Matthieu 12 | F13: Luc 1.32-33
... A261: Apocalypse | B261: 22 | C261: 241 | D261: Psaumes 133–135 | E261: Apocalypse 22 | F261: —

Sheet Index des thèmes
A1: Thème | B1: Code interne | C1: Type de relation privilégié
A2: Adoration | B2: worship | C2: Continuité théologique et pratique
A3: Alliance et promesses | B3: covenant | C3: Écho thématique
A4: Alliance nuptiale | B4: bride | C4: Écho thématique
A5: Amour et fidélité | B5: love | C5: Continuité théologique et pratique
A6: Berger et conduite de Dieu | B6: shepherd | C6: Typologie / accomplissement
A7: Chute, péché et besoin de salut | B7: fall | C7: Avertissement / contraste
A8: Création et nouvelle création | B8: creation | C8: Création / accomplissement eschatologique
A9: Désert, épreuve et persévérance | B9: wilderness | C9: Avertissement / contraste
A10: Eau, vie et purification | B10: water | C10: Typologie / accomplissement
A11: Espérance | B11: hope | C11: Création / accomplissement eschatologique
A12: Exode, salut et libération | B12: exodus | C12: Typologie / accomplissement
... A58: Vérité | B58: truth | C58: Écho thématique

Sheet Audio quotidien
A1: Jour | B1: Date | C1: Lecture AT | D1: Lecture NT | E1: Passage miroir | F1: URL audio AT | G1: URL audio NT | H1: URL audio miroir
A2: 1 | B2: 01/01 | C2: Genèse 1–2 | D2: Jean 1.1-5 | E2: — | F2: https://www.bible.com/fr/audio-bible/152/GEN.1.S21 | G2: https://www.bible.com/fr/audio-bible/152/JHN.1.S21
A3: 2 | B3: 02/01 | C3: Genèse 3–5 | D3: Romains 5 | E3: Éphésiens 2.4-10 | F3: https://www.bible.com/fr/audio-bible/152/GEN.3.S21 | G3: https://www.bible.com/fr/audio-bible/152/ROM.5.S21 | H3: https://www.bible.com/fr/audio-bible/152/EPH.2.S21
A4: 3 | B4: 03/01 | C4: Genèse 6–7 | D4: Hébreux 8.6-13 | E4: — | F4: https://www.bible.com/fr/audio-bible/152/GEN.6.S21 | G4: https://www.bible.com/fr/audio-bible/152/HEB.8.S21
A5: 4 | B5: 04/01 | C5: Genèse 8–10 | D5: Actes 15 | E5: — | F5: https://www.bible.com/fr/audio-bible/152/GEN.8.S21 | G5: https://www.bible.com/fr/audio-bible/152/ACT.15.S21
A6: 5 | B6: 05/01 | C6: Genèse 11–12 | D6: Actes 13 | E6: — | F6: https://www.bible.com/fr/audio-bible/152/GEN.11.S21 | G6: https://www.bible.com/fr/audio-bible/152/ACT.13.S21
A7: 6 | B7: 06/01 | C7: Genèse 13–15 | D7: Matthieu 15 | E7: — | F7: https://www.bible.com/fr/audio-bible/152/GEN.13.S21 | G7: https://www.bible.com/fr/audio-bible/152/MAT.15.S21
A8: 7 | B8: 07/01 | C8: Genèse 16–17 | D8: Matthieu 14 | E8: — | F8: https://www.bible.com/fr/audio-bible/152/GEN.16.S21 | G8: https://www.bible.com/fr/audio-bible/152/MAT.14.S21
A9: 8 | B9: 08/01 | C9: Genèse 18–20 | D9: Éphésiens 2.4-10 | E9: — | F9: https://www.bible.com/fr/audio-bible/152/GEN.18.S21 | G9: https://www.bible.com/fr/audio-bible/152/EPH.2.S21
A10: 9 | B10: 09/01 | C10: Genèse 21–22 | D10: Hébreux 10.10-14 | E10: — | F10: https://www.bible.com/fr/audio-bible/152/GEN.21.S21 | G10: https://www.bible.com/fr/audio-bible/152/HEB.10.S21
A11: 10 | B11: 10/01 | C11: Genèse 23–25 | D11: Hébreux 8.6-13 | E11: — | F11: https://www.bible.com/fr/audio-bible/152/GEN.23.S21 | G11: https://www.bible.com/fr/audio-bible/152/HEB.8.S21
A12: 11 | B12: 11/01 | C12: Genèse 26–27 | D12: Hébreux 8.6-13 | E12: — | F12: https://www.bible.com/fr/audio-bible/152/GEN.26.S21 | G12: https://www.bible.com/fr/audio-bible/152/HEB.8.S21
A13: 12 | B13: 12/01 | C13: Genèse 28–30 | D13: Galates 4 | E13: — | F13: https://www.bible.com/fr/audio-bible/152/GEN.28.S21 | G13: https://www.bible.com/fr/audio-bible/152/GAL.4.S21
A14: 13 | B14: 13/01 | C14: Genèse 31–33 | D14: Matthieu 20 | E14: Hébreux 8.6-13 | F14: https://www.bible.com/fr/audio-bible/152/GEN.31.S21 | G14: https://www.bible.com/fr/audio-bible/152/MAT.20.S21 | H14: https://www.bible.com/fr/audio-bible/152/HEB.8.S21
A15: 14 | B15: 14/01 | C15: Genèse 34–35 | D15: Matthieu 19 | E15: Hébreux 8.6-13 | F15: https://www.bible.com/fr/audio-bible/152/GEN.34.S21 | G15: https://www.bible.com/fr/audio-bible/152/MAT.19.S21 | H15: https://www.bible.com/fr/audio-bible/152/HEB.8.S21
A16: 15 | B16: 15/01 | C16: Genèse 36–38 | D16: Actes 26 | E16: Hébreux 8.6-13 | F16: https://www.bible.com/fr/audio-bible/152/GEN.36.S21 | G16: https://www.bible.com/fr/audio-bible/152/ACT.26.S21 | H16: https://www.bible.com/fr/audio-bible/152/HEB.8.S21
A17: 16 | B17: 16/01 | C17: Genèse 39–40 | D17: Actes 24 | E17: 1 Pierre 2.21-24 | F17: https://www.bible.com/fr/audio-bible/152/GEN.39.S21 | G17: https://www.bible.com/fr/audio-bible/152/ACT.24.S21 | H17: https://www.bible.com/fr/audio-bible/152/1PE.2.S21
A18: 17 | B18: 17/01 | C18: Genèse 41–43 | D18: Actes 23 | E18: 1 Pierre 2.21-24 | F18: https://www.bible.com/fr/audio-bible/152/GEN.41.S21 | G18: https://www.bible.com/fr/audio-bible/152/ACT.23.S21 | H18: https://www.bible.com/fr/audio-bible/152/1PE.2.S21
A19: 18 | B19: 18/01 | C19: Genèse 44–45 | D19: Philémon 1 | E19: Éphésiens 4.31-32 | F19: https://www.bible.com/fr/audio-bible/152/GEN.44.S21 | G19: https://www.bible.com/fr/audio-bible/152/PHM.1.S21 | H19: https://www.bible.com/fr/audio-bible/152/EPH.4.S21
A20: 19 | B20: 19/01 | C20: Genèse 46–48 | D20: Actes 16 | E20: — | F20: https://www.bible.com/fr/audio-bible/152/GEN.46.S21 | G20: https://www.bible.com/fr/audio-bible/152/ACT.16.S21
A21: 20 | B21: 20/01 | C21: Genèse 49–50 | D21: Actes 14 | E21: Éphésiens 3.4-6 | F21: https://www.bible.com/fr/audio-bible/152/GEN.49.S21 | G21: https://www.bible.com/fr/audio-bible/152/ACT.14.S21 | H21: https://www.bible.com/fr/audio-bible/152/EPH.3.S21
A22: 21 | B22: 21/01 | C22: Exode 1–3 | D22: 1 Corinthiens 10.1-4 | E22: — | F22: https://www.bible.com/fr/audio-bible/152/EXO.1.S21 | G22: https://www.bible.com/fr/audio-bible/152/1CO.10.S21
A23: 22 | B23: 22/01 | C23: Exode 4–5 | D23: 1 Corinthiens 10 | E23: — | F23: https://www.bible.com/fr/audio-bible/152/EXO.4.S21 | G23: https://www.bible.com/fr/audio-bible/152/1CO.10.S21
A24: 23 | B24: 23/01 | C24: Exode 6–8 | D24: 1 Corinthiens 9 | E24: — | F24: https://www.bible.com/fr/audio-bible/152/EXO.6.S21 | G24: https://www.bible.com/fr/audio-bible/152/1CO.9.S21
A25: 24 | B25: 24/01 | C25: Exode 9–11 | D25: 1 Corinthiens 8 | E25: — | F25: https://www.bible.com/fr/audio-bible/152/EXO.9.S21 | G25: https://www.bible.com/fr/audio-bible/152/1CO.8.S21
A26: 25 | B26: 25/01 | C26: Exode 12–13 | D26: Marc 14 | E26: — | F26: https://www.bible.com/fr/audio-bible/152/EXO.12.S21 | G26: https://www.bible.com/fr/audio-bible/152/MRK.14.S21
A27: 26 | B27: 26/01 | C27: Exode 14–16 | D27: Jean 6 | E27: — | F27: https://www.bible.com/fr/audio-bible/152/EXO.14.S21 | G27: https://www.bible.com/fr/audio-bible/152/JHN.6.S21
A28: 27 | B28: 27/01 | C28: Exode 17–18 | D28: Hébreux 3.7-19 | E28: — | F28: https://www.bible.com/fr/audio-bible/152/EXO.17.S21 | G28: https://www.bible.com/fr/audio-bible/152/HEB.3.S21
A29: 28 | B29: 28/01 | C29: Exode 19–21 | D29: Hébreux 8.6-13 | E29: — | F29: https://www.bible.com/fr/audio-bible/152/EXO.19.S21 | G29: https://www.bible.com/fr/audio-bible/152/HEB.8.S21
A30: 29 | B30: 29/01 | C30: Exode 22–23 | D30: Hébreux 8.6-13 | E30: — | F30: https://www.bible.com/fr/audio-bible/152/EXO.22.S21 | G30: https://www.bible.com/fr/audio-bible/152/HEB.8.S21
A31: 30 | B31: 30/01 | C31: Exode 24–26 | D31: Hébreux 7.23-28 | E31: — | F31: https://www.bible.com/fr/audio-bible/152/EXO.24.S21 | G31: https://www.bible.com/fr/audio-bible/152/HEB.7.S21
A32: 31 | B32: 31/01 | C32: Exode 27–28 | D32: Hébreux 7.23-28 | E32: — | F32: https://www.bible.com/fr/audio-bible/152/EXO.27.S21 | G32: https://www.bible.com/fr/audio-bible/152/HEB.7.S21
A33: 32 | B33: 01/02 | C33: Exode 29–31 | D33: Hébreux 7.23-28 | E33: — | F33: https://www.bible.com/fr/audio-bible/152/EXO.29.S21 | G33: https://www.bible.com/fr/audio-bible/152/HEB.7.S21
... A35: 34 | B35: 03/02 | C35: Exode 34–36 | D35: Romains 9 | E35: — | F35: https://www.bible.com/fr/audio-bible/152/EXO.34.S21 | G35: https://www.bible.com/fr/audio-bible/152/ROM.9.S21
A36: 35 | B36: 04/02 | C36: Exode 37–39 | D36: Galates 6 | E36: Hébreux 9.1-12 | F36: https://www.bible.com/fr/audio-bible/152/EXO.37.S21 | G36: https://www.bible.com/fr/audio-bible/152/GAL.6.S21 | H36: https://www.bible.com/fr/audio-bible/152/HEB.9.S21
A37: 36 | B37: 05/02 | C37: Exode 40 ; Lévitique 1 | D37: Hébreux 10 | E37: — | F37: https://www.bible.com/fr/audio-bible/152/LEV.1.S21 | G37: https://www.bible.com/fr/audio-bible/152/HEB.10.S21
A38: 37 | B38: 06/02 | C38: Lévitique 2–4 | D38: Hébreux 10.10-14 | E38: — | F38: https://www.bible.com/fr/audio-bible/152/LEV.2.S21 | G38: https://www.bible.com/fr/audio-bible/152/HEB.10.S21
A39: 38 | B39: 07/02 | C39: Lévitique 5–6 | D39: Hébreux 10.10-14 | E39: — | F39: https://www.bible.com/fr/audio-bible/152/LEV.5.S21 | G39: https://www.bible.com/fr/audio-bible/152/HEB.10.S21
A40: 39 | B40: 08/02 | C40: Lévitique 7–9 | D40: Hébreux 9 | E40: — | F40: https://www.bible.com/fr/audio-bible/152/LEV.7.S21 | G40: https://www.bible.com/fr/audio-bible/152/HEB.9.S21
A41: 40 | B41: 09/02 | C41: Lévitique 10–11 | D41: Matthieu 23 | E41: Hébreux 7.23-28 | F41: https://www.bible.com/fr/audio-bible/152/LEV.10.S21 | G41: https://www.bible.com/fr/audio-bible/152/MAT.23.S21 | H41: https://www.bible.com/fr/audio-bible/152/HEB.7.S21
...

Sheet Sources audio
A1: Source | B1: Version | C1: Adresse | D1: Utilisation dans le plan
A2: YouVersion / Bible App | B2: Segond 21 (S21) | C2: https://www.bible.com/fr/audio-bible-app-versions/152-s21-la-bible-segond-21 | D2: Source principale : audio complet de l'Ancien et du Nouveau Testament, chapitre par chapitre.
A3: BibleAudio | B3: Louis Segond 1910 | C3: https://bibleaudio.org/ecouter/louis-segond/ | D3: Alternative gratuite en Louis Segond 1910 ; navigation par livres/listes de lecture.
A5: Comment utiliser les liens audio
A6: 1. | B6: Dans « Plan annuel », cliquer sur ▶ Écouter AT pour ouvrir le premier chapitre AT du jour.
A7: 2. | B7: Quand plusieurs chapitres sont prévus, utiliser « chapitre suivant » dans YouVersion jusqu'à la fin de la référence du jour.
A8: 3. | B8: Cliquer ensuite sur ▶ Écouter NT. Pour un passage limité à quelques versets, l'audio ouvre le chapitre entier : arrêter à la référence indiquée si souhaité.
A9: 4. | B9: Si un passage miroir est indiqué, le bouton bleu ▶ Écouter miroir ouvre le chapitre correspondant.
A10: 5. | B10: Les liens principaux utilisent Segond 21 car l'audio YouVersion couvre toute la Bible dans cette version.

Sheet Lecture du jour
A1: LA BIBLE EN UN AN — LECTURE DU JOUR
A3: Choisir le jour : | C3: 1 | E3: ="Jour "&$C$3&" • "&INDEX('Plan annuel'!$B$2:$B$366,$C$3) -> Jour 1 • 01/01
A5: =INDEX('Plan annuel'!$H$2:$H$366,$C$3) -> Création et nouvelle création
A7: ANCIEN TESTAMENT
A8: =INDEX('Plan annuel'!$D$2:$D$366,$C$3) -> Genèse 1–2
A10: =HYPERLINK(INDEX('Audio quotidien'!$F$2:$F$366,$C$3),"▶ ÉCOUTER L’ANCIEN TESTAMENT") -> ▶ ÉCOUTER L’ANCIEN TESTAMENT
A13: NOUVEAU TESTAMENT
A14: =INDEX('Plan annuel'!$E$2:$E$366,$C$3) -> Jean 1.1-5
A16: =HYPERLINK(INDEX('Audio quotidien'!$G$2:$G$366,$C$3),"▶ ÉCOUTER LE NOUVEAU TESTAMENT") -> ▶ ÉCOUTER LE NOUVEAU TESTAMENT
A19: PASSAGE MIROIR
A20: =IF(INDEX('Plan annuel'!$G$2:$G$366,$C$3)="—","Aucun passage miroir aujourd’hui",INDEX('Plan annuel'!$G$2:$G$366,$C$3)) -> Aucun passage miroir aujourd’hui
A22: =IF(INDEX('Plan annuel'!$G$2:$G$366,$C$3)="—","",HYPERLINK(INDEX('Audio quotidien'!$H$2:$H$366,$C$3),"▶ ÉCOUTER LE PASSAGE MIROIR"))
A25: LIEN THÉOLOGIQUE
A26: =INDEX('Plan annuel'!$I$2:$I$366,$C$3) -> Création / accomplissement eschatologique
A27: =INDEX('Plan annuel'!$J$2:$J$366,$C$3) -> Le texte de l'AT contemple l'œuvre créatrice de Dieu ; le NT la relit à la lumière du Christ et de la nouvelle création.
A32: Suivi : | C32: =INDEX('Plan annuel'!$K$2:$K$366,$C$3) -> À lire
A34: Notes personnelles
A35: =IF(INDEX('Plan annuel'!$L$2:$L$366,$C$3)="","",INDEX('Plan annuel'!$L$2:$L$366,$C$3))
A40: Sur iPhone : si les boutons de cette feuille ne s’ouvrent pas, utilisez la feuille « Liens mobile » (URL directes) ou la page HTML mobile fournie séparément.

Sheet Liens mobile
A1: Jour | B1: Date | C1: Lecture | D1: Référence | E1: Chapitre audio | F1: URL directe | G1: Thème | H1: Conseil
A2: 1 | B2: 01/01 | C2: AT | D2: Genèse 1–2 | E2: Genèse 1 | F2: https://www.bible.com/fr/audio-bible/152/GEN.1.S21 | G2: Création et nouvelle création | H2: Touchez ou copiez l’URL dans Safari
A3: 1 | B3: 01/01 | C3: AT | D3: Genèse 1–2 | E3: Genèse 2 | F3: https://www.bible.com/fr/audio-bible/152/GEN.2.S21
A4: 1 | B4: 01/01 | C4: NT | D4: Jean 1.1-5 | E4: Jean 1 | F4: https://www.bible.com/fr/audio-bible/152/JHN.1.S21
A5: 2 | B5: 02/01 | C5: AT | D5: Genèse 3–5 | E5: Genèse 3 | F5: https://www.bible.com/fr/audio-bible/152/GEN.3.S21 | G5: Grâce et pardon | H5: Touchez ou copiez l’URL dans Safari
A6: 2 | B6: 02/01 | C6: AT | D6: Genèse 3–5 | E6: Genèse 4 | F6: https://www.bible.com/fr/audio-bible/152/GEN.4.S21
A7: 2 | B7: 02/01 | C7: AT | D7: Genèse 3–5 | E7: Genèse 5 | F7: https://www.bible.com/fr/audio-bible/152/GEN.5.S21
A8: 2 | B8: 02/01 | C8: NT | D8: Romains 5 | E8: Romains 5 | F8: https://www.bible.com/fr/audio-bible/152/ROM.5.S21
A9: 2 | B9: 02/01 | C9: Miroir | D9: Éphésiens 2.4-10 | E9: Éphésiens 2 | F9: https://www.bible.com/fr/audio-bible/152/EPH.2.S21
A10: 3 | B10: 03/01 | C10: AT | D10: Genèse 6–7 | E10: Genèse 6 | F10: https://www.bible.com/fr/audio-bible/152/GEN.6.S21 | G10: Alliance et promesses | H10: Touchez ou copiez l’URL dans Safari
A11: 3 | B11: 03/01 | C11: AT | D11: Genèse 6–7 | E11: Genèse 7 | F11: https://www.bible.com/fr/audio-bible/152/GEN.7.S21
A12: 3 | B12: 03/01 | C12: NT | D12: Hébreux 8.6-13 | E12: Hébreux 8 | F12: https://www.bible.com/fr/audio-bible/152/HEB.8.S21
A13: 4 | B13: 04/01 | C13: AT | D13: Genèse 8–10 | E13: Genèse 8 | F13: https://www.bible.com/fr/audio-bible/152/GEN.8.S21 | G13: Nations et universalité du salut | H13: Touchez ou copiez l’URL dans Safari
A14: 4 | B14: 04/01 | C14: AT | D14: Genèse 8–10 | E14: Genèse 9 | F14: https://www.bible.com/fr/audio-bible/152/GEN.9.S21
A15: 4 | B15: 04/01 | C15: AT | D15: Genèse 8–10 | E15: Genèse 10 | F15: https://www.bible.com/fr/audio-bible/152/GEN.10.S21
A16: 4 | B16: 04/01 | C16: NT | D16: Actes 15 | E16: Actes 15 | F16: https://www.bible.com/fr/audio-bible/152/ACT.15.S21
A17: 5 | B17: 05/01 | C17: AT | D17: Genèse 11–12 | E17: Genèse 11 | F17: https://www.bible.com/fr/audio-bible/152/GEN.11.S21 | G17: Nations et universalité du salut | H17: Touchez ou copiez l’URL dans Safari
A18: 5 | B18: 05/01 | C18: AT | D18: Genèse 11–12 | E18: Genèse 12 | F18: https://www.bible.com/fr/audio-bible/152/GEN.12.S21
A19: 5 | B19: 05/01 | C19: NT | D19: Actes 13 | E19: Actes 13 | F19: https://www.bible.com/fr/audio-bible/152/ACT.13.S21
A20: 6 | B20: 06/01 | C20: AT | D20: Genèse 13–15 | E20: Genèse 13 | F20: https://www.bible.com/fr/audio-bible/152/GEN.13.S21 | G20: Nations et universalité du salut | H20: Touchez ou copiez l’URL dans Safari
A21: 6 | B21: 06/01 | C21: AT | D21: Genèse 13–15 | E21: Genèse 14 | F21: https://www.bible.com/fr/audio-bible/152/GEN.14.S21
A22: 6 | B22: 06/01 | C22: AT | D22: Genèse 13–15 | E22: Genèse 15 | F22: https://www.bible.com/fr/audio-bible/152/GEN.15.S21
A23: 6 | B23: 06/01 | C23: NT | D23: Matthieu 15 | E23: Matthieu 15 | F23: https://www.bible.com/fr/audio-bible/152/MAT.15.S21
A24: 7 | B24: 07/01 | C24: AT | D24: Genèse 16–17 | E24: Genèse 16 | F24: https://www.bible.com/fr/audio-bible/152/GEN.16.S21 | G24: Nations et universalité du salut | H24: Touchez ou copiez l’URL dans Safari
A25: 7 | B25: 07/01 | C25: AT | D25: Genèse 16–17 | E25: Genèse 17 | F25: https://www.bible.com/fr/audio-bible/152/GEN.17.S21
A26: 7 | B26: 07/01 | C26: NT | D26: Matthieu 14 | E26: Matthieu 14 | F26: https://www.bible.com/fr/audio-bible/152/MAT.14.S21
A27: 8 | B27: 08/01 | C27: AT | D27: Genèse 18–20 | E27: Genèse 18 | F27: https://www.bible.com/fr/audio-bible/152/GEN.18.S21 | G27: Grâce et pardon | H27: Touchez ou copiez l’URL dans Safari
A28: 8 | B28: 08/01 | C28: AT | D28: Genèse 18–20 | E28: Genèse 19 | F28: https://www.bible.com/fr/audio-bible/152/GEN.19.S21
A29: 8 | B29: 08/01 | C29: AT | D29: Genèse 18–20 | E29: Genèse 20 | F29: https://www.bible.com/fr/audio-bible/152/GEN.20.S21
A30: 8 | B30: 08/01 | C30: NT | D30: Éphésiens 2.4-10 | E30: Éphésiens 2 | F30: https://www.bible.com/fr/audio-bible/152/EPH.2.S21
A31: 9 | B31: 09/01 | C31: AT | D31: Genèse 21–22 | E31: Genèse 21 | F31: https://www.bible.com/fr/audio-bible/152/GEN.21.S21 | G31: Sacrifice et expiation | H31: Touchez ou copiez l’URL dans Safari
A32: 9 | B32: 09/01 | C32: AT | D32: Genèse 21–22 | E32: Genèse 22 | F32: https://www.bible.com/fr/audio-bible/152/GEN.22.S21
A33: 9 | B33: 09/01 | C33: NT | D33: Hébreux 10.10-14 | E33: Hébreux 10 | F33: https://www.bible.com/fr/audio-bible/152/HEB.10.S21
A34: 10 | B34: 10/01 | C34: AT | D34: Genèse 23–25 | E34: Genèse 23 | F34: https://www.bible.com/fr/audio-bible/152/GEN.23.S21 | G34: Alliance et promesses | H34: Touchez ou copiez l’URL dans Safari
A35: 10 | B35: 10/01 | C35: AT | D35: Genèse 23–25 | E35: Genèse 24 | F35: https://www.bible.com/fr/audio-bible/152/GEN.24.S21
A36: 10 | B36: 10/01 | C36: AT | D36: Genèse 23–25 | E36: Genèse 25 | F36: https://www.bible.com/fr/audio-bible/152/GEN.25.S21
A37: 10 | B37: 10/01 | C37: NT | D37: Hébreux 8.6-13 | E37: Hébreux 8 | F37: https://www.bible.com/fr/audio-bible/152/HEB.8.S21
A38: 11 | B38: 11/01 | C38: AT | D38: Genèse 26–27 | E38: Genèse 26 | F38: https://www.bible.com/fr/audio-bible/152/GEN.26.S21 | G38: Alliance et promesses | H38: Touchez ou copiez l’URL dans Safari
A39: 11 | B39: 11/01 | C39: AT | D39: Genèse 26–27 | E39: Genèse 27 | F39: https://www.bible.com/fr/audio-bible/152/GEN.27.S21
A40: 11 | B40: 11/01 | C40: NT | D40: Hébreux 8.6-13 | E40: Hébreux 8 | F40: https://www.bible.com/fr/audio-bible/152/HEB.8.S21
...
